Workbook

Sheet Dashboard
A1: DSA 90-Day Interview Preparation Dashboard
A3: Metric | B3: Value
A4: Total DSA Problems | B4: ='DSA Problems'!A172 -> 171
A5: Completed Problems | B5: =COUNTIF('DSA Problems'!F:F,"Completed") -> 9
A6: In Progress | B6: =COUNTIF('DSA Problems'!F:F,"In Progress") -> 0
A7: Needs Revision | B7: =COUNTIF('DSA Problems'!F:F,"Needs Revision") -> 40
A8: Remaining | B8: =B4-B5 -> 162
A9: Completion % | B9: =IF(B4=0,0,B5/B4) -> 0.052631579
A11: Target Problems | B11: 180
A12: Target Study Days | B12: 90
A13: Target Mock Interviews | B13: 4
A15: Recommended Daily DSA Time | B15: 2.5–3 hours
A16: Target Role | B16: Python Backend Engineer / SDE
A18: Core Stack | B18: Python + FastAPI + PostgreSQL + Redis + Kafka + AWS
A20: Priority Patterns | B20: Hashing, Two Pointers, Sliding Window, Binary Search, Trees, Graphs, Heap

Sheet 90 Day Plan
A1: Day | B1: Week | C1: Phase | D1: Primary Pattern | E1: Daily Target | F1: DSA Problems | G1: Python Focus | H1: SQL/Backend Focus | I1: Status | J1: Hours | K1: Notes
A2: 1 | B2: 1 | C2: Foundation | D2: Hashing | E2: 2–3 problems | G2: Python DSA implementation | H2: FastAPI / PostgreSQL | I2: Not Started
A3: 2 | B3: 1 | C3: Foundation | D3: Hashing | E3: 2–3 problems | G3: Python DSA implementation | H3: SQL + Backend fundamentals | I3: Not Started
A4: 3 | B4: 1 | C4: Foundation | D4: Hashing | E4: 2–3 problems | G4: Python DSA implementation | H4: FastAPI / PostgreSQL | I4: Not Started
A5: 4 | B5: 1 | C5: Foundation | D5: Two Pointers | E5: 2–3 problems | G5: Python DSA implementation | H5: SQL + Backend fundamentals | I5: Not Started
A6: 5 | B6: 1 | C6: Foundation | D6: Two Pointers | E6: 2–3 problems | G6: Python DSA implementation | H6: FastAPI / PostgreSQL | I6: Not Started
A7: 6 | B7: 1 | C7: Foundation | D7: Two Pointers | E7: 2–3 problems | G7: Python DSA implementation | H7: SQL + Backend fundamentals | I7: Not Started
A8: 7 | B8: 1 | C8: Foundation | D8: Revision | E8: 2–3 problems + revision | G8: Python DSA implementation | H8: FastAPI / PostgreSQL | I8: Not Started
A9: 8 | B9: 2 | C9: Foundation | D9: Prefix/Suffix | E9: 2–3 problems | G9: Python DSA implementation | H9: SQL + Backend fundamentals | I9: Not Started
A10: 9 | B10: 2 | C10: Foundation | D10: Prefix/Suffix | E10: 2–3 problems | G10: Python DSA implementation | H10: FastAPI / PostgreSQL | I10: Not Started
A11: 10 | B11: 2 | C11: Foundation | D11: Prefix/Suffix | E11: 2–3 problems | G11: Python DSA implementation | H11: SQL + Backend fundamentals | I11: Not Started
A12: 11 | B12: 2 | C12: Foundation | D12: Sliding Window | E12: 2–3 problems | G12: Python DSA implementation | H12: FastAPI / PostgreSQL | I12: Not Started
A13: 12 | B13: 2 | C13: Foundation | D13: Sliding Window | E13: 2–3 problems | G13: Python DSA implementation | H13: SQL + Backend fundamentals | I13: Not Started
... A91: 90 | B91: 13 | C91: Final Revision | D91: Final Assessment | E91: 2–3 problems + revision | G91: Python interview practice | H91: SQL + Backend fundamentals | I91: Not Started

Sheet DSA Problems
A1: ID | B1: Pattern | C1: Problem | D1: Difficulty | E1: Priority | F1: Status | G1: Time Taken (min) | H1: Solved Without Help | I1: Revision 1 | J1: Revision 2 | K1: Revision 3 | L1: Notes
A2: 1 | B2: Hashing | C2: Two Sum | D2: Easy | E2: HIGH | F2: Completed | G2: 30 | H2: Yes
A3: 2 | B3: Hashing | C3: Contains Duplicate | D3: Easy | E3: HIGH | F3: Completed | G3: 20 | H3: Yes
A4: 3 | B4: Hashing | C4: Valid Anagram | D4: Easy | E4: HIGH | F4: Completed | G4: 30 | H4: Yes
A5: 4 | B5: Hashing | C5: Ransom Note | D5: Easy | E5: HIGH | F5: Completed | G5: 45 | H5: No
A6: 5 | B6: Hashing | C6: Intersection of Two Arrays | D6: Easy | E6: HIGH | F6: Completed | G6: 30 | H6: No
A7: 6 | B7: Hashing | C7: Isomorphic Strings | D7: Easy | E7: HIGH | F7: Completed | G7: 25 | H7: No
A8: 7 | B8: Hashing | C8: Word Pattern | D8: Easy | E8: HIGH | F8: Completed | G8: 30 | H8: No
A9: 8 | B9: Hashing | C9: Happy Number | D9: Easy | E9: HIGH | F9: Completed | G9: 40 | H9: No
A10: 9 | B10: Hashing | C10: Group Anagrams | D10: Medium | E10: HIGH | F10: Completed | G10: 20 | H10: No
A11: 10 | B11: Hashing | C11: Top K Frequent Elements | D11: Medium | E11: HIGH | F11: Needs Revision | G11: 35 | H11: No | L11: required more alogorithms
A12: 11 | B12: Hashing | C12: Longest Consecutive Sequence | D12: Medium | E12: HIGH | F12: Needs Revision | G12: 40 | H12: No
A13: 12 | B13: Hashing | C13: Contains Duplicate II | D13: Easy | E13: HIGH | F13: Needs Revision | G13: 30 | H13: No | L13: required sliding window
A14: 13 | B14: Hashing | C14: Majority Element | D14: Easy | E14: HIGH | F14: Not Started | H14: No | L14: required more alogorithms
A15: 14 | B15: Hashing | C15: Subarray Sum Equals K | D15: Medium | E15: HIGH | F15: Needs Revision | G15: 25 | H15: No
A16: 15 | B16: Hashing | C16: Longest Substring with At Most K Distinct Characters | D16: Medium | E16: HIGH | F16: Not Started | H16: No
A17: 16 | B17: Two Pointers | C17: Valid Palindrome | D17: Easy | E17: HIGH | F17: Needs Revision | G17: 20 | H17: No
A18: 17 | B18: Two Pointers | C18: Two Sum II | D18: Medium | E18: HIGH | F18: Needs Revision | G18: 30 | H18: No
A19: 18 | B19: Two Pointers | C19: Remove Duplicates from Sorted Array | D19: Easy | E19: HIGH | F19: Needs Revision | G19: 20 | H19: No
A20: 19 | B20: Two Pointers | C20: Remove Element | D20: Easy | E20: HIGH | F20: Needs Revision | G20: 20 | H20: No
A21: 20 | B21: Two Pointers | C21: Move Zeroes | D21: Easy | E21: HIGH | F21: Needs Revision | G21: 25 | H21: No
A22: 21 | B22: Two Pointers | C22: Merge Sorted Array | D22: Easy | E22: HIGH | F22: Needs Revision | G22: 30 | H22: No
A23: 22 | B23: Two Pointers | C23: Squares of a Sorted Array | D23: Easy | E23: HIGH | F23: Needs Revision | G23: 30 | H23: No
A24: 23 | B24: Two Pointers | C24: Container With Most Water | D24: Medium | E24: HIGH | F24: Needs Revision | G24: 20 | H24: No
A25: 24 | B25: Two Pointers | C25: 3Sum | D25: Medium | E25: HIGH | F25: Not Started | H25: No
A26: 25 | B26: Two Pointers | C26: 4Sum | D26: Medium | E26: HIGH | F26: Not Started | H26: No
A27: 26 | B27: Two Pointers | C27: Trapping Rain Water | D27: Hard | E27: HIGH | F27: Not Started | H27: No
A28: 27 | B28: Two Pointers | C28: Sort Colors | D28: Medium | E28: HIGH | F28: Not Started | H28: No
A29: 28 | B29: Sliding Window | C29: Maximum Average Subarray I | D29: Easy | E29: HIGH | F29: Needs Revision | G29: 30 | H29: No
A30: 29 | B30: Sliding Window | C30: Maximum Sum Subarray of Size K | D30: Easy | E30: HIGH | F30: Needs Revision | G30: 30 | H30: No
A31: 30 | B31: Sliding Window | C31: Longest Substring Without Repeating Characters | D31: Medium | E31: HIGH | F31: Needs Revision | G31: 40 | H31: No
A32: 31 | B32: Sliding Window | C32: Longest Repeating Character Replacement | D32: Medium | E32: HIGH | F32: Needs Revision | G32: 40 | H32: No
A33: 32 | B33: Sliding Window | C33: Permutation in String | D33: Medium | E33: HIGH | F33: Needs Revision | G33: 40 | H33: No
A34: 33 | B34: Sliding Window | C34: Find All Anagrams in a String | D34: Medium | E34: HIGH | F34: Needs Revision | G34: 40 | H34: No
A35: 34 | B35: Sliding Window | C35: Minimum Size Subarray Sum | D35: Medium | E35: HIGH | F35: Needs Revision | G35: 40 | H35: No
A36: 35 | B36: Sliding Window | C36: Minimum Window Substring | D36: Hard | E36: HIGH | F36: Needs Revision | G36: 45 | H36: No
A37: 36 | B37: Sliding Window | C37: Longest Subarray of 1s After Deleting One Element | D37: Medium | E37: HIGH | F37: Needs Revision | G37: 25 | H37: No
A38: 37 | B38: Sliding Window | C38: Max Consecutive Ones III | D38: Medium | E38: HIGH | F38: Needs Revision | G38: 25 | H38: No
A39: 38 | B39: Sliding Window | C39: Fruit Into Baskets | D39: Medium | E39: HIGH | F39: Needs Revision | G39: 25 | H39: No
A40: 39 | B40: Sliding Window | C40: Longest Substring with At Most K Distinct Characters | D40: Medium | E40: HIGH | F40: Needs Revision | G40: 25 | H40: No
...

Sheet Pattern Summary
A1: Pattern | B1: Problem Count | C1: Priority | D1: Completed | E1: Remaining | F1: Completion %
A2: Hashing | B2: 15 | C2: HIGH | D2: =COUNTIFS('DSA Problems'!B:B,A2,'DSA Problems'!F:F,"Completed") -> 9 | E2: =B2-D2 -> 6 | F2: =IF(B2=0,0,D2/B2) -> 0.6
A3: Two Pointers | B3: 12 | C3: HIGH | D3: =COUNTIFS('DSA Problems'!B:B,A3,'DSA Problems'!F:F,"Completed") -> 0 | E3: =B3-D3 -> 12 | F3: =IF(B3=0,0,D3/B3) -> 0
A4: Sliding Window | B4: 12 | C4: HIGH | D4: =COUNTIFS('DSA Problems'!B:B,A4,'DSA Problems'!F:F,"Completed") -> 0 | E4: =B4-D4 -> 12 | F4: =IF(B4=0,0,D4/B4) -> 0
A5: Prefix/Suffix | B5: 8 | C5: MEDIUM | D5: =COUNTIFS('DSA Problems'!B:B,A5,'DSA Problems'!F:F,"Completed") -> 0 | E5: =B5-D5 -> 8 | F5: =IF(B5=0,0,D5/B5) -> 0
A6: Binary Search | B6: 12 | C6: HIGH | D6: =COUNTIFS('DSA Problems'!B:B,A6,'DSA Problems'!F:F,"Completed") -> 0 | E6: =B6-D6 -> 12 | F6: =IF(B6=0,0,D6/B6) -> 0
A7: Stack | B7: 10 | C7: HIGH | D7: =COUNTIFS('DSA Problems'!B:B,A7,'DSA Problems'!F:F,"Completed") -> 0 | E7: =B7-D7 -> 10 | F7: =IF(B7=0,0,D7/B7) -> 0
A8: Queue/Deque | B8: 6 | C8: MEDIUM | D8: =COUNTIFS('DSA Problems'!B:B,A8,'DSA Problems'!F:F,"Completed") -> 0 | E8: =B8-D8 -> 6 | F8: =IF(B8=0,0,D8/B8) -> 0
A9: Linked List | B9: 12 | C9: MEDIUM | D9: =COUNTIFS('DSA Problems'!B:B,A9,'DSA Problems'!F:F,"Completed") -> 0 | E9: =B9-D9 -> 12 | F9: =IF(B9=0,0,D9/B9) -> 0
A10: Heap/Priority Queue | B10: 10 | C10: HIGH | D10: =COUNTIFS('DSA Problems'!B:B,A10,'DSA Problems'!F:F,"Completed") -> 0 | E10: =B10-D10 -> 10 | F10: =IF(B10=0,0,D10/B10) -> 0
A11: Intervals | B11: 8 | C11: MEDIUM | D11: =COUNTIFS('DSA Problems'!B:B,A11,'DSA Problems'!F:F,"Completed") -> 0 | E11: =B11-D11 -> 8 | F11: =IF(B11=0,0,D11/B11) -> 0
A12: Trees | B12: 15 | C12: HIGH | D12: =COUNTIFS('DSA Problems'!B:B,A12,'DSA Problems'!F:F,"Completed") -> 0 | E12: =B12-D12 -> 15 | F12: =IF(B12=0,0,D12/B12) -> 0
A13: Graphs | B13: 15 | C13: HIGH | D13: =COUNTIFS('DSA Problems'!B:B,A13,'DSA Problems'!F:F,"Completed") -> 0 | E13: =B13-D13 -> 15 | F13: =IF(B13=0,0,D13/B13) -> 0
... A16: Dynamic Programming | B16: 20 | C16: HIGH | D16: =COUNTIFS('DSA Problems'!B:B,A16,'DSA Problems'!F:F,"Completed") -> 0 | E16: =B16-D16 -> 20 | F16: =IF(B16=0,0,D16/B16) -> 0

Sheet Revision Tracker
A1: Problem ID | B1: Problem | C1: Pattern | D1: Original Status | E1: Revision 1 | F1: Revision 2 | G1: Revision 3 | H1: Can Solve Without Help? | I1: Mistake / Weakness
A2: ='DSA Problems'!A2 -> 1 | B2: ='DSA Problems'!C2 -> Two Sum | C2: ='DSA Problems'!B2 -> Hashing | D2: ='DSA Problems'!F2 -> Completed | H2: No
A3: ='DSA Problems'!A3 -> 2 | B3: ='DSA Problems'!C3 -> Contains Duplicate | C3: ='DSA Problems'!B3 -> Hashing | D3: ='DSA Problems'!F3 -> Completed | H3: No
A4: ='DSA Problems'!A4 -> 3 | B4: ='DSA Problems'!C4 -> Valid Anagram | C4: ='DSA Problems'!B4 -> Hashing | D4: ='DSA Problems'!F4 -> Completed | H4: No
A5: ='DSA Problems'!A5 -> 4 | B5: ='DSA Problems'!C5 -> Ransom Note | C5: ='DSA Problems'!B5 -> Hashing | D5: ='DSA Problems'!F5 -> Completed | H5: No
A6: ='DSA Problems'!A6 -> 5 | B6: ='DSA Problems'!C6 -> Intersection of Two Arrays | C6: ='DSA Problems'!B6 -> Hashing | D6: ='DSA Problems'!F6 -> Completed | H6: No
A7: ='DSA Problems'!A7 -> 6 | B7: ='DSA Problems'!C7 -> Isomorphic Strings | C7: ='DSA Problems'!B7 -> Hashing | D7: ='DSA Problems'!F7 -> Completed | H7: No
A8: ='DSA Problems'!A8 -> 7 | B8: ='DSA Problems'!C8 -> Word Pattern | C8: ='DSA Problems'!B8 -> Hashing | D8: ='DSA Problems'!F8 -> Completed | H8: No
A9: ='DSA Problems'!A9 -> 8 | B9: ='DSA Problems'!C9 -> Happy Number | C9: ='DSA Problems'!B9 -> Hashing | D9: ='DSA Problems'!F9 -> Completed | H9: No
A10: ='DSA Problems'!A10 -> 9 | B10: ='DSA Problems'!C10 -> Group Anagrams | C10: ='DSA Problems'!B10 -> Hashing | D10: ='DSA Problems'!F10 -> Completed | H10: No
A11: ='DSA Problems'!A11 -> 10 | B11: ='DSA Problems'!C11 -> Top K Frequent Elements | C11: ='DSA Problems'!B11 -> Hashing | D11: ='DSA Problems'!F11 -> Needs Revision | H11: No
A12: ='DSA Problems'!A12 -> 11 | B12: ='DSA Problems'!C12 -> Longest Consecutive Sequence | C12: ='DSA Problems'!B12 -> Hashing | D12: ='DSA Problems'!F12 -> Needs Revision | H12: No
A13: ='DSA Problems'!A13 -> 12 | B13: ='DSA Problems'!C13 -> Contains Duplicate II | C13: ='DSA Problems'!B13 -> Hashing | D13: ='DSA Problems'!F13 -> Needs Revision | H13: No
... A172: ='DSA Problems'!A172 -> 171 | B172: ='DSA Problems'!C172 -> Distinct Subsequences | C172: ='DSA Problems'!B172 -> Dynamic Programming | D172: ='DSA Problems'!F172 -> Not Started | H172: No
